<?xml version="1.0" encoding="UTF-8"?>
<testng-results skipped="0" failed="1" ignored="0" total="1" passed="0">
  <reporter-output>
  </reporter-output>
  <suite name="Suite" duration-ms="18" started-at="2017-07-28T12:31:32Z" finished-at="2017-07-28T12:31:32Z">
    <groups>
    </groups>
    <test name="Test" duration-ms="18" started-at="2017-07-28T12:31:32Z" finished-at="2017-07-28T12:31:32Z">
      <class name="testv6.NewTest">
        <test-method status="FAIL" signature="a()[pri:0, instance:testv6.NewTest@2d6a9952]" name="a" duration-ms="5" started-at="2017-07-28T14:31:32Z" finished-at="2017-07-28T14:31:32Z">
          <exception class="java.lang.AssertionError">
            <message>
              <![CDATA[expected [1] but found [0]]]>
            </message>
            <full-stacktrace>
              <![CDATA[java.lang.AssertionError: expected [1] but found [0]
	at org.testng.Assert.fail(Assert.java:93)
	at org.testng.Assert.failNotEquals(Assert.java:512)
	at org.testng.Assert.assertEqualsImpl(Assert.java:134)
	at org.testng.Assert.assertEquals(Assert.java:115)
	at org.testng.Assert.assertEquals(Assert.java:388)
	at org.testng.Assert.assertEquals(Assert.java:398)
	at testv6.NewTest.a(NewTest.java:35)
	at sun.reflect.NativeMethodAccessorImpl.invoke0(Native Method)
	at sun.reflect.NativeMethodAccessorImpl.invoke(NativeMethodAccessorImpl.java:62)
	at sun.reflect.DelegatingMethodAccessorImpl.invoke(DelegatingMethodAccessorImpl.java:43)
	at java.lang.reflect.Method.invoke(Method.java:498)
	at org.testng.internal.MethodInvocationHelper.invokeMethod(MethodInvocationHelper.java:108)
	at org.testng.internal.Invoker.invokeMethod(Invoker.java:661)
	at org.testng.internal.Invoker.invokeTestMethod(Invoker.java:869)
	at org.testng.internal.Invoker.invokeTestMethods(Invoker.java:1193)
	at org.testng.internal.TestMethodWorker.invokeTestMethods(TestMethodWorker.java:126)
	at org.testng.internal.TestMethodWorker.run(TestMethodWorker.java:109)
	at org.testng.TestRunner.privateRun(TestRunner.java:744)
	at org.testng.TestRunner.run(TestRunner.java:602)
	at org.testng.SuiteRunner.runTest(SuiteRunner.java:380)
	at org.testng.SuiteRunner.runSequentially(SuiteRunner.java:375)
	at org.testng.SuiteRunner.privateRun(SuiteRunner.java:340)
	at org.testng.SuiteRunner.run(SuiteRunner.java:289)
	at org.testng.SuiteRunnerWorker.runSuite(SuiteRunnerWorker.java:52)
	at org.testng.SuiteRunnerWorker.run(SuiteRunnerWorker.java:86)
	at org.testng.TestNG.runSuitesSequentially(TestNG.java:1301)
	at org.testng.TestNG.runSuitesLocally(TestNG.java:1226)
	at org.testng.TestNG.runSuites(TestNG.java:1144)
	at org.testng.TestNG.run(TestNG.java:1115)
	at org.testng.TestNG.privateMain(TestNG.java:1442)
	at org.testng.TestNG.main(TestNG.java:1411)
]]>
            </full-stacktrace>
          </exception> <!-- java.lang.AssertionError -->
          <reporter-output>
          </reporter-output>
        </test-method> <!-- a -->
      </class> <!-- testv6.NewTest -->
    </test> <!-- Test -->
  </suite> <!-- Suite -->
</testng-results>
